[2021-05-13 15:11:03 -0700] [8609] [INFO] Starting gunicorn 20.0.4
[2021-05-13 15:11:03 -0700] [8609] [INFO] Listening at: http://127.0.0.1:8000 (8609)
[2021-05-13 15:11:03 -0700] [8609] [INFO] Using worker: uvicorn.workers.UvicornWorker
[2021-05-13 15:11:03 -0700] [8611] [INFO] Booting worker with pid: 8611
[2021-05-13 15:11:03 -0700] [8612] [INFO] Booting worker with pid: 8612
[2021-05-13 15:11:03 -0700] [8613] [INFO] Booting worker with pid: 8613
[2021-05-13 15:11:03 -0700] [8614] [INFO] Booting worker with pid: 8614
[2021-05-13 15:11:03 -0700] [8611] [INFO] Started server process [8611]
[2021-05-13 15:11:03 -0700] [8611] [INFO] Waiting for application startup.
[2021-05-13 15:11:03 -0700] [8611] [INFO] Application startup complete.
[2021-05-13 15:11:03 -0700] [8612] [INFO] Started server process [8612]
[2021-05-13 15:11:03 -0700] [8612] [INFO] Waiting for application startup.
[2021-05-13 15:11:03 -0700] [8612] [INFO] Application startup complete.
[2021-05-13 15:11:03 -0700] [8613] [INFO] Started server process [8613]
[2021-05-13 15:11:03 -0700] [8613] [INFO] Waiting for application startup.
[2021-05-13 15:11:03 -0700] [8613] [INFO] Application startup complete.
[2021-05-13 15:11:03 -0700] [8614] [INFO] Started server process [8614]
[2021-05-13 15:11:03 -0700] [8614] [INFO] Waiting for application startup.
[2021-05-13 15:11:03 -0700] [8614] [INFO] Application startup complete.
[2021-05-13 15:12:06 -0700] [8613] [ERROR] Exception in ASGI application
Traceback (most recent call last):
  File "/home/ritwik/.local/lib/python3.8/site-packages/uvicorn/protocols/http/httptools_impl.py", line 390, in run_asgi
    result = await app(self.scope, self.receive, self.send)
  File "/home/ritwik/.local/lib/python3.8/site-packages/uvicorn/middleware/proxy_headers.py", line 45, in __call__
    return await self.app(scope, receive, send)
  File "/home/ritwik/.local/lib/python3.8/site-packages/fastapi/applications.py", line 179, in __call__
    await super().__call__(scope, receive, send)
  File "/home/ritwik/.local/lib/python3.8/site-packages/starlette/applications.py", line 111, in __call__
    await self.middleware_stack(scope, receive, send)
  File "/home/ritwik/.local/lib/python3.8/site-packages/starlette/middleware/errors.py", line 181, in __call__
    raise exc from None
  File "/home/ritwik/.local/lib/python3.8/site-packages/starlette/middleware/errors.py", line 159, in __call__
    await self.app(scope, receive, _send)
  File "/home/ritwik/.local/lib/python3.8/site-packages/starlette/exceptions.py", line 82, in __call__
    raise exc from None
  File "/home/ritwik/.local/lib/python3.8/site-packages/starlette/exceptions.py", line 71, in __call__
    await self.app(scope, receive, sender)
  File "/home/ritwik/.local/lib/python3.8/site-packages/starlette/routing.py", line 566, in __call__
    await route.handle(scope, receive, send)
  File "/home/ritwik/.local/lib/python3.8/site-packages/starlette/routing.py", line 227, in handle
    await self.app(scope, receive, send)
  File "/home/ritwik/.local/lib/python3.8/site-packages/starlette/routing.py", line 41, in app
    response = await func(request)
  File "/home/ritwik/.local/lib/python3.8/site-packages/fastapi/routing.py", line 182, in app
    raw_response = await run_endpoint_function(
  File "/home/ritwik/.local/lib/python3.8/site-packages/fastapi/routing.py", line 133, in run_endpoint_function
    return await dependant.call(**values)
  File "/home/ritwik/git_hub/TreasureHunt/backend/python/main.py", line 289, in exit_challenge
    response.status_code = user.exit_challenge(json.name)
  File "/home/ritwik/git_hub/TreasureHunt/backend/python/utils.py", line 25, in wrapper
    return func(user, *args, **kwargs)
  File "/home/ritwik/git_hub/TreasureHunt/backend/python/user.py", line 582, in exit_challenge
    return self.start_challenge(get_challenge_id(name), param='false')
  File "/home/ritwik/git_hub/TreasureHunt/backend/python/utils.py", line 40, in get_challenge_id
    return db.select('select challenge_id from challenges where name = %s', params=(name,), dict_cursor=True)[0].get('challenge_id')
IndexError: tuple index out of range
[2021-05-13 16:14:10 -0700] [8614] [ERROR] Exception in ASGI application
Traceback (most recent call last):
  File "/home/ritwik/.local/lib/python3.8/site-packages/uvicorn/protocols/http/httptools_impl.py", line 390, in run_asgi
    result = await app(self.scope, self.receive, self.send)
  File "/home/ritwik/.local/lib/python3.8/site-packages/uvicorn/middleware/proxy_headers.py", line 45, in __call__
    return await self.app(scope, receive, send)
  File "/home/ritwik/.local/lib/python3.8/site-packages/fastapi/applications.py", line 179, in __call__
    await super().__call__(scope, receive, send)
  File "/home/ritwik/.local/lib/python3.8/site-packages/starlette/applications.py", line 111, in __call__
    await self.middleware_stack(scope, receive, send)
  File "/home/ritwik/.local/lib/python3.8/site-packages/starlette/middleware/errors.py", line 181, in __call__
    raise exc from None
  File "/home/ritwik/.local/lib/python3.8/site-packages/starlette/middleware/errors.py", line 159, in __call__
    await self.app(scope, receive, _send)
  File "/home/ritwik/.local/lib/python3.8/site-packages/starlette/exceptions.py", line 82, in __call__
    raise exc from None
  File "/home/ritwik/.local/lib/python3.8/site-packages/starlette/exceptions.py", line 71, in __call__
    await self.app(scope, receive, sender)
  File "/home/ritwik/.local/lib/python3.8/site-packages/starlette/routing.py", line 566, in __call__
    await route.handle(scope, receive, send)
  File "/home/ritwik/.local/lib/python3.8/site-packages/starlette/routing.py", line 227, in handle
    await self.app(scope, receive, send)
  File "/home/ritwik/.local/lib/python3.8/site-packages/starlette/routing.py", line 44, in app
    await response(scope, receive, send)
  File "/home/ritwik/.local/lib/python3.8/site-packages/starlette/responses.py", line 290, in __call__
    raise RuntimeError(f"File at path {self.path} does not exist.")
RuntimeError: File at path /home/ritwik/git_hub/TreasureHunt/backend/tmp/dpfp21 does not exist.
Exception in thread Thread-4:
Traceback (most recent call last):
  File "/usr/lib/python3.8/threading.py", line 932, in _bootstrap_inner
    self.run()
  File "/usr/lib/python3.8/threading.py", line 1254, in run
    self.function(*self.args, **self.kwargs)
  File "/home/ritwik/git_hub/TreasureHunt/backend/python/user.py", line 216, in <lambda>
    Timer(1, lambda: os.remove(local_path)).start()
FileNotFoundError: [Errno 2] No such file or directory: '/home/ritwik/git_hub/TreasureHunt/backend/tmp/dpfp21'
[2021-05-13 16:18:32 -0700] [8613] [ERROR] Exception in ASGI application
Traceback (most recent call last):
  File "/home/ritwik/.local/lib/python3.8/site-packages/uvicorn/protocols/http/httptools_impl.py", line 390, in run_asgi
    result = await app(self.scope, self.receive, self.send)
  File "/home/ritwik/.local/lib/python3.8/site-packages/uvicorn/middleware/proxy_headers.py", line 45, in __call__
    return await self.app(scope, receive, send)
  File "/home/ritwik/.local/lib/python3.8/site-packages/fastapi/applications.py", line 179, in __call__
    await super().__call__(scope, receive, send)
  File "/home/ritwik/.local/lib/python3.8/site-packages/starlette/applications.py", line 111, in __call__
    await self.middleware_stack(scope, receive, send)
  File "/home/ritwik/.local/lib/python3.8/site-packages/starlette/middleware/errors.py", line 181, in __call__
    raise exc from None
  File "/home/ritwik/.local/lib/python3.8/site-packages/starlette/middleware/errors.py", line 159, in __call__
    await self.app(scope, receive, _send)
  File "/home/ritwik/.local/lib/python3.8/site-packages/starlette/exceptions.py", line 82, in __call__
    raise exc from None
  File "/home/ritwik/.local/lib/python3.8/site-packages/starlette/exceptions.py", line 71, in __call__
    await self.app(scope, receive, sender)
  File "/home/ritwik/.local/lib/python3.8/site-packages/starlette/routing.py", line 566, in __call__
    await route.handle(scope, receive, send)
  File "/home/ritwik/.local/lib/python3.8/site-packages/starlette/routing.py", line 227, in handle
    await self.app(scope, receive, send)
  File "/home/ritwik/.local/lib/python3.8/site-packages/starlette/routing.py", line 44, in app
    await response(scope, receive, send)
  File "/home/ritwik/.local/lib/python3.8/site-packages/starlette/responses.py", line 290, in __call__
    raise RuntimeError(f"File at path {self.path} does not exist.")
RuntimeError: File at path /home/ritwik/git_hub/TreasureHunt/backend/tmp/dpfp21 does not exist.
Exception in thread Thread-3:
Traceback (most recent call last):
  File "/usr/lib/python3.8/threading.py", line 932, in _bootstrap_inner
    self.run()
  File "/usr/lib/python3.8/threading.py", line 1254, in run
    self.function(*self.args, **self.kwargs)
  File "/home/ritwik/git_hub/TreasureHunt/backend/python/user.py", line 216, in <lambda>
    Timer(1, lambda: os.remove(local_path)).start()
FileNotFoundError: [Errno 2] No such file or directory: '/home/ritwik/git_hub/TreasureHunt/backend/tmp/dpfp21'
[2021-05-13 16:19:28 -0700] [8614] [ERROR] Exception in ASGI application
Traceback (most recent call last):
  File "/home/ritwik/.local/lib/python3.8/site-packages/uvicorn/protocols/http/httptools_impl.py", line 390, in run_asgi
    result = await app(self.scope, self.receive, self.send)
  File "/home/ritwik/.local/lib/python3.8/site-packages/uvicorn/middleware/proxy_headers.py", line 45, in __call__
    return await self.app(scope, receive, send)
  File "/home/ritwik/.local/lib/python3.8/site-packages/fastapi/applications.py", line 179, in __call__
    await super().__call__(scope, receive, send)
  File "/home/ritwik/.local/lib/python3.8/site-packages/starlette/applications.py", line 111, in __call__
    await self.middleware_stack(scope, receive, send)
  File "/home/ritwik/.local/lib/python3.8/site-packages/starlette/middleware/errors.py", line 181, in __call__
    raise exc from None
  File "/home/ritwik/.local/lib/python3.8/site-packages/starlette/middleware/errors.py", line 159, in __call__
    await self.app(scope, receive, _send)
  File "/home/ritwik/.local/lib/python3.8/site-packages/starlette/exceptions.py", line 82, in __call__
    raise exc from None
  File "/home/ritwik/.local/lib/python3.8/site-packages/starlette/exceptions.py", line 71, in __call__
    await self.app(scope, receive, sender)
  File "/home/ritwik/.local/lib/python3.8/site-packages/starlette/routing.py", line 566, in __call__
    await route.handle(scope, receive, send)
  File "/home/ritwik/.local/lib/python3.8/site-packages/starlette/routing.py", line 227, in handle
    await self.app(scope, receive, send)
  File "/home/ritwik/.local/lib/python3.8/site-packages/starlette/routing.py", line 44, in app
    await response(scope, receive, send)
  File "/home/ritwik/.local/lib/python3.8/site-packages/starlette/responses.py", line 290, in __call__
    raise RuntimeError(f"File at path {self.path} does not exist.")
RuntimeError: File at path /home/ritwik/git_hub/TreasureHunt/backend/tmp/dpfp21 does not exist.
Exception in thread Thread-5:
Traceback (most recent call last):
  File "/usr/lib/python3.8/threading.py", line 932, in _bootstrap_inner
    self.run()
  File "/usr/lib/python3.8/threading.py", line 1254, in run
    self.function(*self.args, **self.kwargs)
  File "/home/ritwik/git_hub/TreasureHunt/backend/python/user.py", line 216, in <lambda>
    Timer(1, lambda: os.remove(local_path)).start()
FileNotFoundError: [Errno 2] No such file or directory: '/home/ritwik/git_hub/TreasureHunt/backend/tmp/dpfp21'
[2021-05-13 16:39:36 -0700] [8612] [ERROR] Exception in ASGI application
Traceback (most recent call last):
  File "/home/ritwik/.local/lib/python3.8/site-packages/uvicorn/protocols/http/httptools_impl.py", line 390, in run_asgi
    result = await app(self.scope, self.receive, self.send)
  File "/home/ritwik/.local/lib/python3.8/site-packages/uvicorn/middleware/proxy_headers.py", line 45, in __call__
    return await self.app(scope, receive, send)
  File "/home/ritwik/.local/lib/python3.8/site-packages/fastapi/applications.py", line 179, in __call__
    await super().__call__(scope, receive, send)
  File "/home/ritwik/.local/lib/python3.8/site-packages/starlette/applications.py", line 111, in __call__
    await self.middleware_stack(scope, receive, send)
  File "/home/ritwik/.local/lib/python3.8/site-packages/starlette/middleware/errors.py", line 181, in __call__
    raise exc from None
  File "/home/ritwik/.local/lib/python3.8/site-packages/starlette/middleware/errors.py", line 159, in __call__
    await self.app(scope, receive, _send)
  File "/home/ritwik/.local/lib/python3.8/site-packages/starlette/exceptions.py", line 82, in __call__
    raise exc from None
  File "/home/ritwik/.local/lib/python3.8/site-packages/starlette/exceptions.py", line 71, in __call__
    await self.app(scope, receive, sender)
  File "/home/ritwik/.local/lib/python3.8/site-packages/starlette/routing.py", line 566, in __call__
    await route.handle(scope, receive, send)
  File "/home/ritwik/.local/lib/python3.8/site-packages/starlette/routing.py", line 227, in handle
    await self.app(scope, receive, send)
  File "/home/ritwik/.local/lib/python3.8/site-packages/starlette/routing.py", line 44, in app
    await response(scope, receive, send)
  File "/home/ritwik/.local/lib/python3.8/site-packages/starlette/responses.py", line 290, in __call__
    raise RuntimeError(f"File at path {self.path} does not exist.")
RuntimeError: File at path /home/ritwik/git_hub/TreasureHunt/backend/tmp/dpfp21 does not exist.
Exception in thread Thread-1:
Traceback (most recent call last):
  File "/usr/lib/python3.8/threading.py", line 932, in _bootstrap_inner
    self.run()
  File "/usr/lib/python3.8/threading.py", line 1254, in run
    self.function(*self.args, **self.kwargs)
  File "/home/ritwik/git_hub/TreasureHunt/backend/python/user.py", line 216, in <lambda>
    Timer(1, lambda: os.remove(local_path)).start()
FileNotFoundError: [Errno 2] No such file or directory: '/home/ritwik/git_hub/TreasureHunt/backend/tmp/dpfp21'
